<?xml version='1.0' encoding='ASCII'?>
<sdf version="1.7">
  <model name="skuid">
    <self_collide>false</self_collide>
    <pose>0 0 0.4 0 0 0</pose>
    <static>false</static>
    <!-- BASE -->

    <macro name="base_inertia" params="m x y z">
      <inertia>
      <ixx>"${m*(y*y+z*z)/12}"</ixx>
      <ixy>0</ixy>
      <ixz>0</ixz>
      <iyy>"${m*(x*x+z*z)/12}"</iyy>
      <iyz>0</iyz>
      <izz>"${m*(x*x+y*y)/2}"</izz>
      </inertia>
    </macro>

    <link name="base_link">
      <pose>0 0 0 0 0 0</pose>
      <inertial>
        <pose>-0.1 0 0.1 0 0 0</pose>
        <mass>200</mass>
        <base_inertia m="200.0" x="0.95" y="2.0" z="0.4" />
      </inertial>
      <collision name="base_link_collision">
        <pose>0 0 0 0 0 1.57</pose>
        <geometry>
          <box>
            <size>0.95 2.0 0.4</size>
          </box>
        </geometry>
      </collision>
      <visual name="base_link_visual">
        <pose>0 0 0 0 0 1.57</pose>
        <geometry>
          <mesh>
            <uri>meshes/base/skuid_base.dae</uri>
          </mesh>
        </geometry>
        <material>
          <diffuse>1 1 1 1</diffuse>
        </material>
      </visual>
    </link>

    <link name="imu_link">
      <pose>0.15 0 0.25 0 0 0</pose>
      <sensor name="imu" type="imu">
        <update_rate>30</update_rate>
        <visualize>false</visualize>
      </sensor>
    </link>

    <joint name="imu_link_joint" type="fixed">
      <child>imu_link</child>
      <parent>base_link</parent>
    </joint>

    <!-- SENSORS -->

    <link name="camera_front">
      <pose relative_to="base_link">0.85 0 0.125 0 0 0</pose>
      <sensor name="color" type="camera">
        <pose>0 0.0325 0.0125 0 0 0</pose>
        <update_rate>6</update_rate>
        <always_on>0</always_on>
        <camera>
          <horizontal_fov>1.20427718</horizontal_fov>
          <image>
            <width>848</width>
            <height>480</height>
          </image>
          <clip>
            <near>0.1</near>
            <far>50</far>
          </clip>
          <lens>
            <intrinsics>
              <fx>615.9603271484375</fx>
              <fy>616.227294921875</fy>
              <cx>419.83026123046875</cx>
              <cy>245.1431427001953</cy>
              <s>0</s>
            </intrinsics>
          </lens>
        </camera>
      </sensor>
      <sensor name="depth" type="depth_camera">
        <pose>0 0.0175 0.0125 0 0 0</pose>
        <update_rate>6</update_rate>
        <always_on>0</always_on>
        <camera>
          <horizontal_fov>1.51843645</horizontal_fov>
          <image>
            <width>848</width>
            <height>480</height>
            <format>R_FLOAT32</format>
          </image>
          <clip>
            <near>0.1</near>
            <far>10</far>
          </clip>
          <lens>
            <intrinsics>
              <fx>421.61578369140625</fx>
              <fy>421.61578369140625</fy>
              <cx>422.2854309082031</cx>
              <cy>236.57237243652344</cy>
              <s>0</s>
            </intrinsics>
          </lens>
        </camera>
      </sensor>
    </link>

    <joint name="camera_front_joint" type="fixed">
      <child>camera_front</child>
      <parent>base_link</parent>
    </joint>

    <link name="camera_back">
      <pose relative_to="base_link">-0.5 0 0.175 0 0 3.141592654</pose>
      <sensor name="color" type="camera">
        <pose>0 0.0325 0.0125 0 0 0</pose>
        <update_rate>6</update_rate>
        <always_on>0</always_on>
        <camera>
          <horizontal_fov>1.20427718</horizontal_fov>
          <image>
            <width>848</width>
            <height>480</height>
          </image>
          <clip>
            <near>0.1</near>
            <far>50</far>
          </clip>
          <lens>
            <intrinsics>
              <fx>615.9603271484375</fx>
              <fy>616.227294921875</fy>
              <cx>419.83026123046875</cx>
              <cy>245.1431427001953</cy>
              <s>0</s>
            </intrinsics>
          </lens>
        </camera>
      </sensor>
      <sensor name="depth" type="depth_camera">
        <pose>0 0.0175 0.0125 0 0 0</pose>
        <update_rate>6</update_rate>
        <always_on>0</always_on>
        <camera>
          <horizontal_fov>1.51843645</horizontal_fov>
          <image>
            <width>848</width>
            <height>480</height>
            <format>R_FLOAT32</format>
          </image>
          <clip>
            <near>0.1</near>
            <far>10</far>
          </clip>
          <lens>
            <intrinsics>
              <fx>421.61578369140625</fx>
              <fy>421.61578369140625</fy>
              <cx>422.2854309082031</cx>
              <cy>236.57237243652344</cy>
              <s>0</s>
            </intrinsics>
          </lens>
        </camera>
      </sensor>
    </link>

    <joint name="camera_back_joint" type="fixed">
      <child>camera_back</child>
      <parent>base_link</parent>
    </joint>

    <link name="scan">
      <pose relative_to="base_link">0 0 0.4 0 0 0</pose>
      <visual name="velodyne_base">
        <pose>0 0 0 0 0 0</pose>
        <geometry>
          <cylinder>
            <radius>0.06</radius>
            <length>0.0015</length>
          </cylinder>
        </geometry>
      </visual>
      <!-- Bottom cylinder of Ouster/Velodyne 3D Lidar -->
      <visual name="velodyne_base_link_visual_base">
        <pose>0 0 0 0 0 0</pose>
        <geometry>
          <mesh>
            <scale>1 1 1</scale>
            <uri>meshes/VLP16_base_1.dae</uri>
          </mesh>
        </geometry>
      </visual>
      <!-- Top cylinder of Ouster/Velodyne 3D Lidar -->
      <visual name="velodyne_base_link_visual_sensor">
        <pose>0 0 0 0 0 0</pose>
        <geometry>
          <mesh>
            <scale>1 1 1</scale>
            <uri>meshes/VLP16_base_2.dae</uri>
          </mesh>
        </geometry>
      </visual>
      <!-- Main cylinder of Ouster/Velodyne 3D Lidar -->
      <visual name="base_link_velodyne_visual_scan">
        <pose>0 0 0 0 0 0</pose>
        <geometry>
          <mesh>
            <scale>1 1 1</scale>
            <uri>meshes/VLP16_scan.dae</uri>
          </mesh>
        </geometry>
      </visual>
      <sensor name="scan" type="gpu_lidar">
        <visualize>true</visualize>
        <update_rate>10</update_rate>
        <lidar>
          <scan>
            <horizontal>
              <!-- Real samples value is 1800 -->
              <samples>900</samples>
              <resolution>1</resolution>
              <min_angle>-3.141592654</min_angle>
              <max_angle>3.141592654</max_angle>
            </horizontal>
            <vertical>
              <samples>16</samples>
              <resolution>1</resolution>
              <min_angle>-0.261799388</min_angle>
              <max_angle>0.261799388</max_angle>
            </vertical>
          </scan>
          <range>
            <min>0.2</min>
            <max>100.0</max>
            <resolution>0.01</resolution>
          </range>
        </lidar>
      </sensor>
    </link>

    <joint name="scan_joint" type="fixed">
      <child>scan</child>
      <parent>base_link</parent>
    </joint>

    <!-- WHEELS -->

    <macro name="cylinder_inertia" params="m r h">
      <inertia>
      <ixx>"${m*(3*r*r+h*h)/12}"</ixx>
      <ixy>0</ixy>
      <ixz>0</ixz>
      <iyy>"${m*(3*r*r+h*h)/12}"</iyy>
      <iyz>0</iyz>
      <izz>"${m*r*r/2}"</izz>
      </inertia>
    </macro>

    <link name="wheel_left_front">
      <pose>0.625 0.6 0 -1.57 0 0</pose>
      <inertial>
        <pose>0 0 0 0 0 0</pose>
        <mass>10.0</mass>
        <cylinder_inertia m="10.0" r="0.35" h="0.225" />
      </inertial>
      <collision name="wheel_left_front_collision">
        <pose>0 0 0 1.57 0 0</pose>
        <geometry>
          <!-- <cylinder>
            <radius>0.35</radius>
            <length>0.225</length>
          </cylinder> -->
          <mesh>
            <scale>0.25 0.35 0.25</scale>
            <uri>meshes/wheel/tyre.dae</uri>
          </mesh>
        </geometry>
        <surface>
          <friction>
            <ode>
              <mu>1.01</mu>
              <mu2>1.01</mu2>
              <fdir1>0 0 1</fdir1>
              <slip1>0</slip1>
              <slip2>0</slip2>
            </ode>
          </friction>
          <bounce>
            <restitution_coefficient>0.0</restitution_coefficient>
            <threshold>100000.0</threshold>
          </bounce>
          <contact>
            <ode>
              <soft_cfm>0.0</soft_cfm>
              <soft_erp>0.2</soft_erp>
              <kp>100000.0</kp>
              <kd>1.0</kd>
              <max_vel>100.0</max_vel>
              <min_depth>0.0</min_depth>
            </ode>
          </contact>
        </surface>
        <max_contacts>5</max_contacts>
        <!--<surface>
          <contact>
            <ode>
              <kp>1000000.0</kp>
              <kd>1</kd>
              <min_depth>0.01</min_depth>
              <max_vel>1</max_vel>
            </ode>
          </contact>
          <friction>
            <ode>
              <mu>10</mu>
              <mu2>100</mu2>
              <fdir1>1 0 0</fdir1>
            </ode>
          </friction>
        </surface> -->
      </collision>
      <visual name="wheel_left_front_visual">
        <pose>0 0 0 1.57 0 0</pose>
        <geometry>
          <mesh>
            <scale>0.25 0.35 0.25</scale>
            <uri>meshes/wheel/tyre.dae</uri>
          </mesh>
        </geometry>
        <material>
          <diffuse>1 1 1 1</diffuse>
        </material>
      </visual>
    </link>

    <joint name="wheel_left_front_joint" type="revolute">
      <child>wheel_left_front</child>
      <parent>base_link</parent>
      <axis>
        <xyz>0 0 1</xyz>
        <limit>
          <effort>1000</effort>
        </limit>
        <dynamics>
          <damping>3.0</damping>
          <friction>0.5</friction>
        </dynamics>
      </axis>
    </joint>

    <link name="wheel_right_front">
      <pose>0.625 -0.6 0 -1.57 0 0</pose>
      <inertial>
        <pose>0 0 0 0 0 0</pose>
        <mass>10.0</mass>
        <cylinder_inertia m="10.0" r="0.35" h="0.225" />
      </inertial>
      <collision name="wheel_right_front_collision">
        <pose>0 0 0 1.57 0 0</pose>
        <geometry>
          <!-- <cylinder>
            <radius>0.35</radius>
            <length>0.225</length>
          </cylinder> -->
          <mesh>
            <scale>0.25 0.35 0.25</scale>
            <uri>meshes/wheel/tyre.dae</uri>
          </mesh>
        </geometry>
        <surface>
          <friction>
            <ode>
              <mu>1.01</mu>
              <mu2>1.01</mu2>
              <fdir1>0 0 1</fdir1>
              <slip1>0</slip1>
              <slip2>0</slip2>
            </ode>
          </friction>
          <bounce>
            <restitution_coefficient>0.0</restitution_coefficient>
            <threshold>100000.0</threshold>
          </bounce>
          <contact>
            <ode>
              <soft_cfm>0.0</soft_cfm>
              <soft_erp>0.2</soft_erp>
              <kp>100000.0</kp>
              <kd>1.0</kd>
              <max_vel>100.0</max_vel>
              <min_depth>0.0</min_depth>
            </ode>
          </contact>
        </surface>
        <max_contacts>5</max_contacts>
        <!--<surface>
          <contact>
            <ode>
              <kp>1000000.0</kp>
              <kd>1</kd>
              <min_depth>0.01</min_depth>
              <max_vel>1</max_vel>
            </ode>
          </contact>
          <friction>
            <ode>
              <mu>10</mu>
              <mu2>100</mu2>
              <fdir1>1 0 0</fdir1>
            </ode>
          </friction>
        </surface> -->
      </collision>
      <visual name="wheel_right_front_visual">
        <pose>0 0 0 1.57 0 0</pose>
        <geometry>
          <mesh>
            <scale>0.25 0.35 0.25</scale>
            <uri>meshes/wheel/tyre.dae</uri>
          </mesh>
        </geometry>
        <material>
          <diffuse>1 1 1 1</diffuse>
        </material>
      </visual>
    </link>

    <joint name="wheel_right_front_joint" type="revolute">
      <child>wheel_right_front</child>
      <parent>base_link</parent>
      <axis>
        <xyz>0 0 1</xyz>
        <limit>
          <effort>1000</effort>
        </limit>
        <dynamics>
          <damping>3.0</damping>
          <friction>0.5</friction>
        </dynamics>
      </axis>
    </joint>

    <link name="wheel_left_back">
      <pose>-0.625 0.6 0 -1.57 0 0</pose>
      <inertial>
        <pose>0 0 0 0 0 0</pose>
        <mass>10.0</mass>
        <cylinder_inertia m="10.0" r="0.35" h="0.225" />
      </inertial>
      <collision name="wheel_left_back_collision">
        <pose>0 0 0 1.57 0 0</pose>
        <geometry>
          <!-- <cylinder>
            <radius>0.35</radius>
            <length>0.225</length>
          </cylinder> -->
          <mesh>
            <scale>0.25 0.35 0.25</scale>
            <uri>meshes/wheel/tyre.dae</uri>
          </mesh>
        </geometry>
        <surface>
          <friction>
            <ode>
              <mu>1.01</mu>
              <mu2>1.01</mu2>
              <fdir1>0 0 1</fdir1>
              <slip1>0</slip1>
              <slip2>0</slip2>
            </ode>
          </friction>
          <bounce>
            <restitution_coefficient>0.0</restitution_coefficient>
            <threshold>100000.0</threshold>
          </bounce>
          <contact>
            <ode>
              <soft_cfm>0.0</soft_cfm>
              <soft_erp>0.2</soft_erp>
              <kp>100000.0</kp>
              <kd>1.0</kd>
              <max_vel>100.0</max_vel>
              <min_depth>0.0</min_depth>
            </ode>
          </contact>
        </surface>
        <max_contacts>5</max_contacts>
        <!--<surface>
          <contact>
            <ode>
              <kp>1000000.0</kp>
              <kd>1</kd>
              <min_depth>0.01</min_depth>
              <max_vel>1</max_vel>
            </ode>
          </contact>
          <friction>
            <ode>
              <mu>10</mu>
              <mu2>100</mu2>
              <fdir1>1 0 0</fdir1>
            </ode>
          </friction>
        </surface> -->
      </collision>
      <visual name="wheel_left_back_visual">
        <pose>0 0 0 1.57 0 0</pose>
        <geometry>
          <mesh>
            <scale>0.25 0.35 0.25</scale>
            <uri>meshes/wheel/tyre.dae</uri>
          </mesh>
        </geometry>
        <material>
          <diffuse>1 1 1 1</diffuse>
        </material>
      </visual>
    </link>

    <joint name="wheel_left_back_joint" type="revolute">
      <child>wheel_left_back</child>
      <parent>base_link</parent>
      <axis>
        <xyz>0 0 1</xyz>
        <limit>
          <effort>1000</effort>
        </limit>
        <dynamics>
          <damping>3.0</damping>
          <friction>0.5</friction>
        </dynamics>
      </axis>
    </joint>

    <link name="wheel_right_back">
      <pose>-0.625 -0.6 0 -1.57 0 0</pose>
      <inertial>
        <pose>0 0 0 0 0 0</pose>
        <mass>10.0</mass>
        <cylinder_inertia m="10.0" r="0.35" h="0.225" />
      </inertial>
      <collision name="wheel_right_back_collision">
        <pose>0 0 0 1.57 0 0</pose>
        <geometry>
          <!-- <cylinder>
            <radius>0.35</radius>
            <length>0.225</length>
          </cylinder> -->
          <mesh>
            <scale>0.25 0.35 0.25</scale>
            <uri>meshes/wheel/tyre.dae</uri>
          </mesh>
        </geometry>
        <max_contacts>5</max_contacts>
        <!-- <surface>
          <contact>
            <ode>
              <kp>1000000.0</kp>
              <kd>1</kd>
              <min_depth>0.01</min_depth>
              <max_vel>1</max_vel>
            </ode>
          </contact>
          <friction>
            <ode>
              <mu>10</mu>
              <mu2>100</mu2>
              <fdir1>1 0 0</fdir1>
            </ode>
          </friction>
        </surface> -->
        <surface>
          <friction>
            <ode>
              <mu>1.01</mu>
              <mu2>1.01</mu2>
              <fdir1>0 0 1</fdir1>
              <slip1>0</slip1>
              <slip2>0</slip2>
            </ode>
          </friction>
          <bounce>
            <restitution_coefficient>0.0</restitution_coefficient>
            <threshold>100000.0</threshold>
          </bounce>
          <contact>
            <ode>
              <soft_cfm>0.0</soft_cfm>
              <soft_erp>0.2</soft_erp>
              <kp>100000.0</kp>
              <kd>1.0</kd>
              <max_vel>100.0</max_vel>
              <min_depth>0.0</min_depth>
            </ode>
          </contact>
        </surface>
      </collision>
      <visual name="wheel_right_back_visual">
        <pose>0 0 0 1.57 0 0</pose>
        <geometry>
          <mesh>
            <scale>0.25 0.35 0.25</scale>
            <uri>meshes/wheel/tyre.dae</uri>
          </mesh>
        </geometry>
        <material>
          <diffuse>1 1 1 1</diffuse>
        </material>
      </visual>
    </link>

    <joint name="wheel_right_back_joint" type="revolute">
      <child>wheel_right_back</child>
      <parent>base_link</parent>
      <axis>
        <xyz>0 0 1</xyz>
        <limit>
          <effort>1000</effort>
        </limit>
        <dynamics>
          <damping>3.0</damping>
          <friction>0.5</friction>
        </dynamics>
      </axis>
    </joint>


    <!-- CONTROLERS PLUGINS -->
    <!-- DIFF DRIVE PLUGIN / WHEELS CONTROLER -->
    <plugin filename="ignition-gazebo-diff-drive-system" name="ignition::gazebo::systems::DiffDrive">

      <left_joint>wheel_left_front_joint</left_joint>
      <left_joint>wheel_left_back_joint</left_joint>
      <right_joint>wheel_right_front_joint</right_joint>
      <right_joint>wheel_right_back_joint</right_joint>

      <wheel_separation>1.20</wheel_separation>
      <wheel_radius>0.33</wheel_radius>
      <odom_publish_frequency>1</odom_publish_frequency>

      <frame_id>odom</frame_id>
      <child_frame_id>base_link</child_frame_id>


    </plugin>


    <!-- GROUND ODOMETRY POSITION STATE PUBLISHER (FAKE LOCALIZATION)-->
    <plugin filename="ignition-gazebo-pose-publisher-system" name="ignition::gazebo::systems::PosePublisher">
      <publish_link_pose>true</publish_link_pose>
      <!-- <static_publisher>true</static_publisher> -->
      <publish_collision_pose>false</publish_collision_pose>
      <publish_visual_pose>false</publish_visual_pose>
      <publish_sensor_pose>false</publish_sensor_pose>
      <publish_nested_model_pose>true</publish_nested_model_pose>
      <update_frequency>20</update_frequency>
    </plugin>


    <plugin filename="ignition-gazebo-linearbatteryplugin-system" name="ignition::gazebo::systems::LinearBatteryPlugin">
      <battery_name>linear_battery</battery_name>
      <voltage>24.592</voltage>
      <open_circuit_voltage_constant_coef>24.592</open_circuit_voltage_constant_coef>
      <capacity>1.2009</capacity>
      <power_load>6.5</power_load>
      <fix_issue_225>true</fix_issue_225>
      <enable_recharge>true</enable_recharge>
      <!-- charging I = c / t, discharging I = P / V, 
          charging I should be > discharging I -->
      <charging_time>3.0</charging_time>
      <!-- Consumer-specific -->
      <!-- <power_load>2.1</power_load> -->
      <recharge_by_topic>true</recharge_by_topic>
    </plugin>

  </model>
</sdf>